#VRML_SIM R2021a utf8
WorldInfo {
  basicTimeStep 16
  coordinateSystem "NUE"
  contactProperties [
    ContactProperties {
      coulombFriction [
        3
      ]
    }
  ]
}
Viewpoint {
  orientation -1 -6.342914003581006e-14 -6.137750574662657e-15 0.31079632679498204
  position 0.027238896452729033 0.918917370701638 1.5986383276837015
}
Background {
  skyColor [
    1 1 1
  ]
}
DirectionalLight {
  ambientIntensity 1
  direction 0.1 -0.5 0.3
}
RectangleArena {
  name "arena"
  floorSize 10 10
  floorTileSize 2 2
  floorAppearance PBRAppearance {
    baseColorMap ImageTexture {
      url [
        "textures/parquetry/chequered_parquetry_black_white_shadowman2.jpg"
      ]
    }
    roughness 1
    roughnessMap ImageTexture {
      url [
        "textures/parquetry/chequered_parquetry_roughness.jpg"
      ]
    }
    metalness 0
    normalMap ImageTexture {
      url [
        "textures/parquetry/chequered_parquetry_normal.jpg"
      ]
    }
    occlusionMap ImageTexture {
      url [
        "textures/parquetry/chequered_parquetry_occlusion.jpg"
      ]
    }
  }
  wallHeight 0.3
  wallAppearance PBRAppearance {
    baseColor 0.666667 0 0
    roughness 1
    metalness 0
  }
}
DEF ADEPT Robot {
  translation -8.64401705227979e-07 -0.01019614862572811 0.0001623801301130906
  rotation -0.01703718926952442 -0.6143730362872176 -0.7888317352040418 -4.775574754385268e-06
  children [
    InertialUnit {
      name "imu"
    }
    Camera {
      translation 0 0.200027 -0.17
      rotation -0.0005254768197797978 0.010696096331612412 0.9999426570545816 0.000792689
    }
    Group {
    }
    Shape {
      appearance PBRAppearance {
        baseColor 1 0 0
        roughness 0.3
        metalness 0
      }
      geometry IndexedFaceSet {
        coord Coordinate {
          point [
            -0.1 0.059 0.215
            0.1 0.059 0.215
            0.135 0.059 0.185
            0.135 0.059 -0.095
            0.08 0.059 -0.11
            -0.08 0.059 -0.11
            -0.135 0.059 -0.095
            -0.135 0.059 0.185
            -0.1 0.059 0.215
            -0.1 0.234 0.215
            0.1 0.234 0.215
            0.135 0.234 0.185
            0.135 0.234 -0.095
            0.08 0.234 -0.11
            -0.08 0.234 -0.11
            -0.135 0.234 -0.095
            -0.135 0.234 0.185
            -0.1 0.234 0.215
          ]
        }
        coordIndex [
          8, 7, 6, 5, 4, 3, 2, 1, 0, -1, 9, 10, 11, 12, 13, 14, 15, 16, 17, -1, 0, 1, 10, 9, -1, 1, 2, 11, 10, -1, 2, 3, 12, 11, -1, 3, 4, 13, 12, -1, 4, 5, 14, 13, -1, 5, 6, 15, 14, -1, 6, 7, 16, 15, -1, 7, 8, 17, 16, -1
        ]
      }
    }
    DEF TOP Shape {
      appearance PBRAppearance {
        baseColor 0.636415 0.655556 0.655556
        baseColorMap ImageTexture {
          url [
            "textures/top_3dx_terminator.jpg"
          ]
        }
        roughness 0.3
        metalness 0
        textureTransform TextureTransform {
          center 90 0
          rotation -1.57
        }
      }
      geometry IndexedFaceSet {
        coord Coordinate {
          point [
            0 0.234 -0.174, -0.056 0.234 -0.166, -0.107 0.234 -0.145, -0.155 0.234 -0.112, -0.19 0.234 -0.064, -0.19 0.234 0.074, -0.16 0.234 0.096, -0.16 0.234 0.151, -0.155 0.234 0.2, -0.107 0.234 0.236, -0.056 0.234 0.256, 0 0.234 0.264, 0.056 0.234 0.256, 0.107 0.234 0.236, 0.155 0.234 0.2, 0.16 0.234 0.151, 0.16 0.234 0.096, 0.19 0.234 0.074, 0.19 0.234 -0.064, 0.155 0.234 -0.112, 0.107 0.234 -0.145, 0.056 0.234 -0.166, 0 0.234 -0.174, 0 0.245 -0.174, -0.056 0.245 -0.166, -0.107 0.245 -0.145, -0.155 0.245 -0.112, -0.19 0.245 -0.064, -0.19 0.245 0.074, -0.16 0.245 0.096, -0.16 0.245 0.151, -0.155 0.245 0.2, -0.107 0.245 0.236, -0.056 0.245 0.256, 0 0.245 0.264, 0.056 0.245 0.256, 0.107 0.245 0.236, 0.155 0.245 0.2, 0.16 0.245 0.151, 0.16 0.245 0.096, 0.19 0.245 0.074, 0.19 0.245 -0.064, 0.155 0.245 -0.112, 0.107 0.245 -0.145, 0.056 0.245 -0.166, 0 0.245 -0.174
          ]
        }
        coordIndex [
          22, 21, 20, 19, 18, 17, 16, 15, 14, 13, 12, 11, 10, 9, 8, 7, 6, 5, 4, 3, 2, 1, 0, -1, 23, 24, 25, 26, 27, 28, 29, 30, 31, 32, 33, 34, 35, 36, 37, 38, 39, 40, 41, 42, 43, 44, 45, -1, 0, 1, 24, 23, -1, 1, 2, 25, 24, -1, 2, 3, 26, 25, -1, 3, 4, 27, 26, -1, 4, 5, 28, 27, -1, 5, 6, 29, 28, -1, 6, 7, 30, 29, -1, 7, 8, 31, 30, -1, 8, 9, 32, 31, -1, 9, 10, 33, 32, -1, 10, 11, 34, 33, -1, 11, 12, 35, 34, -1, 12, 13, 36, 35, -1, 13, 14, 37, 36, -1, 14, 15, 38, 37, -1, 15, 16, 39, 38, -1, 16, 17, 40, 39, -1, 17, 18, 41, 40, -1, 18, 19, 42, 41, -1, 19, 20, 43, 42, -1, 20, 21, 44, 43, -1, 21, 22, 45, 44, -1
        ]
      }
    }
    HingeJoint {
      jointParameters HingeJointParameters {
        position 7.251635600285633e-10
        axis -1 0 0
        anchor 0 0.0825 0
      }
      device [
        RotationalMotor {
          name "left wheel motor"
        }
        PositionSensor {
          name "left wheel sensor"
        }
      ]
      endPoint Solid {
        translation -0.16029999999999994 0.0825 0
        rotation 1 0 0 5.240833199274834
        children [
          DEF WHEEL Transform {
            rotation 0 0 1 1.57
            children [
              Shape {
                appearance PBRAppearance {
                  baseColor 0.0037037 0.0037037 0.0037037
                  roughness 0.3
                  metalness 0
                }
                geometry Cylinder {
                  height 0.037
                  radius 0.0825
                }
              }
            ]
          }
        ]
        name "left wheel"
        boundingObject USE WHEEL
        physics Physics {
        }
      }
    }
    HingeJoint {
      jointParameters HingeJointParameters {
        position -3.5593142100111084e-10
        axis -1 0 0
        anchor 0 0.0825 0
      }
      device [
        RotationalMotor {
          name "right wheel motor"
        }
        PositionSensor {
          name "right wheel sensor"
        }
      ]
      endPoint Solid {
        translation 0.16029999999999994 0.0825 0
        rotation 1 0 0 0.9226862310677937
        children [
          USE WHEEL
        ]
        name "right wheel"
        boundingObject USE WHEEL
        physics Physics {
        }
      }
    }
    Shape {
      appearance PBRAppearance {
        baseColor 1 0 0
        roughness 0.3
        metalness 0
      }
      geometry IndexedFaceSet {
        coord Coordinate {
          point [
            0.136 0.184 -0.046
            0.136 0.184 -0.096
            0.101 0.184 -0.134
            0.054 0.184 -0.159
            0 0.184 -0.168
            -0.054 0.184 -0.159
            -0.101 0.184 -0.134
            -0.136 0.184 -0.096
            -0.136 0.184 -0.046
            0.136 0.184 -0.043
            0.136 0.234 -0.046
            0.136 0.234 -0.096
            0.101 0.234 -0.134
            0.054 0.234 -0.159
            0 0.234 -0.168
            -0.054 0.234 -0.159
            -0.101 0.234 -0.134
            -0.136 0.234 -0.096
            -0.136 0.234 -0.046
            0.136 0.234 -0.043
          ]
        }
        coordIndex [
          9, 8, 7, 6, 5, 4, 3, 2, 1, 0, -1, 10, 11, 12, 13, 14, 15, 16, 17, 18, 19, -1, 0, 1, 11, 10, -1, 1, 2, 12, 11, -1, 2, 3, 13, 12, -1, 3, 4, 14, 13, -1, 4, 5, 15, 14, -1, 5, 6, 16, 15, -1, 6, 7, 17, 16, -1, 7, 8, 18, 17, -1, 8, 9, 19, 18, -1, 9, 0, 10, 19, -1
        ]
      }
    }
    Shape {
      appearance PBRAppearance {
        baseColor 1 0 0
        roughness 0.3
        metalness 0
      }
      geometry IndexedFaceSet {
        coord Coordinate {
          point [
            -0.136 0.184 0.135
            -0.136 0.184 0.185
            -0.101 0.184 0.223
            -0.054 0.184 0.248
            0 0.184 0.257
            0.054 0.184 0.248
            0.101 0.184 0.223
            0.136 0.184 0.185
            0.136 0.184 0.135
            -0.136 0.184 0.135
            -0.136 0.234 0.135
            -0.136 0.234 0.185
            -0.101 0.234 0.223
            -0.054 0.234 0.248
            0 0.234 0.257
            0.054 0.234 0.248
            0.101 0.234 0.223
            0.136 0.234 0.185
            0.136 0.234 0.135
            -0.136 0.234 0.135
          ]
        }
        coordIndex [
          9, 8, 7, 6, 5, 4, 3, 2, 1, 0, -1, 10, 11, 12, 13, 14, 15, 16, 17, 18, 19, -1, 0, 1, 11, 10, -1, 1, 2, 12, 11, -1, 2, 3, 13, 12, -1, 3, 4, 14, 13, -1, 4, 5, 15, 14, -1, 5, 6, 16, 15, -1, 6, 7, 17, 16, -1, 7, 8, 18, 17, -1, 8, 9, 19, 18, -1
        ]
      }
    }
    Transform {
      translation 0 0.0325 0.2147
      rotation 0 0 1 1.57
      children [
        Shape {
          appearance PBRAppearance {
            baseColor 0.0037037 0.0037037 0.0037037
            roughness 0.3
            metalness 0
          }
          geometry Cylinder {
            height 0.024
            radius 0.0325
          }
        }
      ]
    }
    DistanceSensor {
      translation -0.027 0.209 -0.164
      rotation 0 1 0 1.745
      children [
        DEF SONAR Transform {
          rotation 0 0 1 1.57
          children [
            Shape {
              appearance PBRAppearance {
                baseColor 1 1 0.0517103
                roughness 0.3
                metalness 0
              }
              geometry Cylinder {
                height 0.002
                radius 0.0175
              }
            }
          ]
        }
      ]
      name "ds0"
      lookupTable [
        0 1024 0
        0.2 1024 0.1
        0.4 0 0.1
      ]
      type "infra-red"
    }
    DistanceSensor {
      translation -0.027 0.209 0.253
      rotation 0 1 0 -1.745
      children [
        USE SONAR
      ]
      name "ds7"
      lookupTable [
        0 1024 0
        0.2 1024 0.1
        0.4 0 0.1
      ]
      type "infra-red"
    }
    DistanceSensor {
      translation 0.027 0.209 0.253
      rotation 0 1 0 -1.396
      children [
        USE SONAR
      ]
      name "ds8"
      lookupTable [
        0 1024 0
        0.2 1024 0.1
        0.4 0 0.1
      ]
      type "infra-red"
    }
    DistanceSensor {
      translation 0.027 0.209 -0.164
      rotation 0 1 0 1.396
      children [
        USE SONAR
      ]
      name "ds15"
      lookupTable [
        0 1024 0
        0.2 1024 0.1
        0.4 0 0.1
      ]
      type "infra-red"
    }
  ]
  name "robot1"
  description "designed by Activmedia Robotics"
  boundingObject Transform {
    translation 0 0.13 0.0447
    children [
      Cylinder {
        height 0.24
        radius 0.219
      }
    ]
  }
  physics Physics {
    mass 0.1
  }
  controller "JavaController"
  customData "3002"
  synchronization FALSE
}
DEF WALL Transform {
  translation 2 0.25 -2
  children [
    DEF WALL Solid {
      children [
        DEF WALL Shape {
          appearance PBRAppearance {
            baseColor 0.666667 0 0
            roughness 1
            metalness 0
          }
          geometry Box {
            size 2 0.5 0.1
          }
        }
      ]
      boundingObject USE WALL
    }
  ]
}
DEF WALL Transform {
  translation -2 0.25 -2
  children [
    DEF WALL Solid {
      children [
        DEF WALL Shape {
          appearance PBRAppearance {
            baseColor 0.666667 0 0
            roughness 1
            metalness 0
          }
          geometry Box {
            size 2 0.5 0.1
          }
        }
      ]
      name "solid(2)"
      boundingObject USE WALL
    }
  ]
}
DEF WALL Transform {
  translation 2 0.25 2
  children [
    DEF WALL Solid {
      children [
        DEF WALL Shape {
          appearance PBRAppearance {
            baseColor 0.666667 0 0
            roughness 1
            metalness 0
          }
          geometry Box {
            size 2 0.5 0.1
          }
        }
      ]
      name "solid(1)"
      boundingObject USE WALL
    }
  ]
}
DEF WALL Transform {
  translation 2 0.25 2
  rotation 0 1 0 1.5707996938995747
  children [
    DEF WALL Solid {
      translation 1.98423 -1.41732e-05 -5.02212
      rotation 0 0 1 4.692820414042842e-06
      children [
        DEF WALL Shape {
          appearance PBRAppearance {
            baseColor 0.666667 0 0
            roughness 1
            metalness 0
          }
          geometry Box {
            size 2 0.5 0.1
          }
        }
      ]
      name "solid(4)"
      boundingObject USE WALL
    }
  ]
}
DEF WALL Transform {
  translation 2 0.25 2
  rotation 0 1 0 1.5708003061004252
  children [
    DEF WALL Solid {
      translation 1.98592 -1.95695e-05 1.04846
      rotation 0 0 1 4.692820414042842e-06
      children [
        DEF WALL Shape {
          appearance PBRAppearance {
            baseColor 0.666667 0 0
            roughness 1
            metalness 0
          }
          geometry Box {
            size 2 0.5 0.1
          }
        }
      ]
      name "solid(5)"
      boundingObject USE WALL
    }
  ]
}
DEF WALL Transform {
  translation -2 0.25 2
  children [
    DEF WALL Solid {
      children [
        DEF WALL Shape {
          appearance PBRAppearance {
            baseColor 0.666667 0 0
            roughness 1
            metalness 0
          }
          geometry Box {
            size 2 0.5 0.1
          }
        }
      ]
      name "solid(3)"
      boundingObject USE WALL
    }
  ]
}
